[2022-12-11T11:22:34.874+0000] {taskinstance.py:1087} INFO - Dependencies all met for <TaskInstance: songs_dag1.ReadData scheduled__2022-12-03T00:00:00+00:00 [queued]>
[2022-12-11T11:22:34.882+0000] {taskinstance.py:1087} INFO - Dependencies all met for <TaskInstance: songs_dag1.ReadData scheduled__2022-12-03T00:00:00+00:00 [queued]>
[2022-12-11T11:22:34.883+0000] {taskinstance.py:1283} INFO - 
--------------------------------------------------------------------------------
[2022-12-11T11:22:34.884+0000] {taskinstance.py:1284} INFO - Starting attempt 5 of 6
[2022-12-11T11:22:34.884+0000] {taskinstance.py:1285} INFO - 
--------------------------------------------------------------------------------
[2022-12-11T11:22:34.893+0000] {taskinstance.py:1304} INFO - Executing <Task(PythonOperator): ReadData> on 2022-12-03 00:00:00+00:00
[2022-12-11T11:22:34.905+0000] {standard_task_runner.py:55} INFO - Started process 2061 to run task
[2022-12-11T11:22:34.925+0000] {standard_task_runner.py:82} INFO - Running: ['***', 'tasks', 'run', 'songs_dag1', 'ReadData', 'scheduled__2022-12-03T00:00:00+00:00', '--job-id', '150', '--raw', '--subdir', 'DAGS_FOLDER/song.py', '--cfg-path', '/tmp/tmpo_nedp4z']
[2022-12-11T11:22:34.932+0000] {standard_task_runner.py:83} INFO - Job 150: Subtask ReadData
[2022-12-11T11:22:35.061+0000] {task_command.py:389} INFO - Running <TaskInstance: songs_dag1.ReadData scheduled__2022-12-03T00:00:00+00:00 [running]> on host 3211e07a3388
[2022-12-11T11:22:35.172+0000] {taskinstance.py:1513} INFO - Exporting the following env vars:
AIRFLOW_CTX_DAG_OWNER=Gama Ariefsadya
AIRFLOW_CTX_DAG_ID=songs_dag1
AIRFLOW_CTX_TASK_ID=ReadData
AIRFLOW_CTX_EXECUTION_DATE=2022-12-03T00:00:00+00:00
AIRFLOW_CTX_TRY_NUMBER=5
AIRFLOW_CTX_DAG_RUN_ID=scheduled__2022-12-03T00:00:00+00:00
[2022-12-11T11:38:14.327+0000] {local_task_job.py:224} WARNING - State of this instance has been externally set to up_for_retry. Terminating instance.
[2022-12-11T11:38:14.335+0000] {process_utils.py:133} INFO - Sending Signals.SIGTERM to group 2061. PIDs of all processes in the group: [2061]
[2022-12-11T11:38:14.336+0000] {process_utils.py:84} INFO - Sending the signal Signals.SIGTERM to group 2061
[2022-12-11T11:54:48.232+0000] {taskinstance.py:1483} ERROR - Received SIGTERM. Terminating subprocesses.
[2022-12-11T11:54:48.308+0000] {taskinstance.py:1772} ERROR - Task failed with exception
Traceback (most recent call last):
  File "/home/airflow/.local/lib/python3.7/site-packages/airflow/models/taskinstance.py", line 1524, in _execute_task_with_callbacks
    result = self._execute_task(context, task_orig)
  File "/home/airflow/.local/lib/python3.7/site-packages/airflow/models/taskinstance.py", line 1585, in _execute_task
    result = execute_callable(context=context)
  File "/home/airflow/.local/lib/python3.7/site-packages/airflow/operators/python.py", line 175, in execute
    return_value = self.execute_callable()
  File "/home/airflow/.local/lib/python3.7/site-packages/airflow/operators/python.py", line 192, in execute_callable
    return self.python_callable(*self.op_args, **self.op_kwargs)
  File "/opt/airflow/dags/song.py", line 21, in ReadData
    database="postgres"
  File "/home/airflow/.local/lib/python3.7/site-packages/psycopg2/__init__.py", line 122, in connect
    conn = _connect(dsn, connection_factory=connection_factory, **kwasync)
psycopg2.OperationalError: connection to server at "103.247.196.249", port 5433 failed: Connection refused
	Is the server running on that host and accepting TCP/IP connections?


During handling of the above exception, another exception occurred:

Traceback (most recent call last):
  File "/home/airflow/.local/lib/python3.7/site-packages/airflow/models/taskinstance.py", line 1378, in _run_raw_task
    self._execute_task_with_callbacks(context, test_mode)
  File "/home/airflow/.local/lib/python3.7/site-packages/airflow/models/taskinstance.py", line 1524, in _execute_task_with_callbacks
    result = self._execute_task(context, task_orig)
  File "/home/airflow/.local/lib/python3.7/site-packages/airflow/models/taskinstance.py", line 1485, in signal_handler
    raise AirflowException("Task received SIGTERM signal")
airflow.exceptions.AirflowException: Task received SIGTERM signal
[2022-12-11T11:54:48.344+0000] {taskinstance.py:1327} INFO - Marking task as FAILED. dag_id=songs_dag1, task_id=ReadData, execution_date=20221203T000000, start_date=20221211T115447, end_date=20221211T115448
[2022-12-11T11:54:48.401+0000] {standard_task_runner.py:105} ERROR - Failed to execute job 150 for task ReadData (Task received SIGTERM signal; 2061)
[2022-12-11T11:54:48.481+0000] {process_utils.py:79} INFO - Process psutil.Process(pid=2061, status='terminated', exitcode=1, started='11:22:34') (2061) terminated with exit code 1
