[2022-12-09T00:38:30.049+0000] {taskinstance.py:1087} INFO - Dependencies all met for <TaskInstance: first_dag.greet scheduled__2022-12-08T00:00:00+00:00 [queued]>
[2022-12-09T00:38:30.056+0000] {taskinstance.py:1087} INFO - Dependencies all met for <TaskInstance: first_dag.greet scheduled__2022-12-08T00:00:00+00:00 [queued]>
[2022-12-09T00:38:30.056+0000] {taskinstance.py:1283} INFO - 
--------------------------------------------------------------------------------
[2022-12-09T00:38:30.057+0000] {taskinstance.py:1284} INFO - Starting attempt 5 of 6
[2022-12-09T00:38:30.057+0000] {taskinstance.py:1285} INFO - 
--------------------------------------------------------------------------------
[2022-12-09T00:38:30.068+0000] {taskinstance.py:1304} INFO - Executing <Task(PythonOperator): greet> on 2022-12-08 00:00:00+00:00
[2022-12-09T00:38:30.074+0000] {standard_task_runner.py:55} INFO - Started process 45508 to run task
[2022-12-09T00:38:30.078+0000] {standard_task_runner.py:82} INFO - Running: ['***', 'tasks', 'run', 'first_dag', 'greet', 'scheduled__2022-12-08T00:00:00+00:00', '--job-id', '77', '--raw', '--subdir', 'DAGS_FOLDER/song.py', '--cfg-path', '/tmp/tmp7xudysa5']
[2022-12-09T00:38:30.084+0000] {standard_task_runner.py:83} INFO - Job 77: Subtask greet
[2022-12-09T00:38:30.131+0000] {task_command.py:389} INFO - Running <TaskInstance: first_dag.greet scheduled__2022-12-08T00:00:00+00:00 [running]> on host d6a5ea0de8c8
[2022-12-09T00:38:30.176+0000] {taskinstance.py:1513} INFO - Exporting the following env vars:
AIRFLOW_CTX_DAG_OWNER=Gama Ariefsadya
AIRFLOW_CTX_DAG_ID=first_dag
AIRFLOW_CTX_TASK_ID=greet
AIRFLOW_CTX_EXECUTION_DATE=2022-12-08T00:00:00+00:00
AIRFLOW_CTX_TRY_NUMBER=5
AIRFLOW_CTX_DAG_RUN_ID=scheduled__2022-12-08T00:00:00+00:00
[2022-12-09T00:38:30.180+0000] {taskinstance.py:1772} ERROR - Task failed with exception
Traceback (most recent call last):
  File "/home/airflow/.local/lib/python3.7/site-packages/airflow/operators/python.py", line 175, in execute
    return_value = self.execute_callable()
  File "/home/airflow/.local/lib/python3.7/site-packages/airflow/operators/python.py", line 192, in execute_callable
    return self.python_callable(*self.op_args, **self.op_kwargs)
  File "/opt/airflow/dags/song.py", line 21, in ReadData
    database="postgres"
  File "/home/airflow/.local/lib/python3.7/site-packages/psycopg2/__init__.py", line 122, in connect
    conn = _connect(dsn, connection_factory=connection_factory, **kwasync)
psycopg2.OperationalError: connection to server at "***-postgres-1" (172.19.0.2), port 5432 failed: FATAL:  password authentication failed for user "postgres"

[2022-12-09T00:38:30.188+0000] {taskinstance.py:1327} INFO - Marking task as UP_FOR_RETRY. dag_id=first_dag, task_id=greet, execution_date=20221208T000000, start_date=20221209T003830, end_date=20221209T003830
[2022-12-09T00:38:30.194+0000] {standard_task_runner.py:105} ERROR - Failed to execute job 77 for task greet (connection to server at "***-postgres-1" (172.19.0.2), port 5432 failed: FATAL:  password authentication failed for user "postgres"
; 45508)
[2022-12-09T00:38:30.211+0000] {local_task_job.py:159} INFO - Task exited with return code 1
[2022-12-09T00:38:30.224+0000] {taskinstance.py:2582} INFO - 0 downstream tasks scheduled from follow-on schedule check
