[2022-12-11T13:06:27.241+0000] {taskinstance.py:1087} INFO - Dependencies all met for <TaskInstance: songs.ReadData scheduled__2022-12-10T00:00:00+00:00 [queued]>
[2022-12-11T13:06:27.248+0000] {taskinstance.py:1087} INFO - Dependencies all met for <TaskInstance: songs.ReadData scheduled__2022-12-10T00:00:00+00:00 [queued]>
[2022-12-11T13:06:27.249+0000] {taskinstance.py:1283} INFO - 
--------------------------------------------------------------------------------
[2022-12-11T13:06:27.250+0000] {taskinstance.py:1284} INFO - Starting attempt 3 of 6
[2022-12-11T13:06:27.250+0000] {taskinstance.py:1285} INFO - 
--------------------------------------------------------------------------------
[2022-12-11T13:06:27.259+0000] {taskinstance.py:1304} INFO - Executing <Task(PythonOperator): ReadData> on 2022-12-10 00:00:00+00:00
[2022-12-11T13:06:27.264+0000] {standard_task_runner.py:55} INFO - Started process 1272 to run task
[2022-12-11T13:06:27.268+0000] {standard_task_runner.py:82} INFO - Running: ['***', 'tasks', 'run', 'songs', 'ReadData', 'scheduled__2022-12-10T00:00:00+00:00', '--job-id', '166', '--raw', '--subdir', 'DAGS_FOLDER/song.py', '--cfg-path', '/tmp/tmpl9l7h_y6']
[2022-12-11T13:06:27.273+0000] {standard_task_runner.py:83} INFO - Job 166: Subtask ReadData
[2022-12-11T13:06:27.327+0000] {task_command.py:389} INFO - Running <TaskInstance: songs.ReadData scheduled__2022-12-10T00:00:00+00:00 [running]> on host 83e68f36074a
[2022-12-11T13:06:27.380+0000] {taskinstance.py:1513} INFO - Exporting the following env vars:
AIRFLOW_CTX_DAG_OWNER=Gama Ariefsadya
AIRFLOW_CTX_DAG_ID=songs
AIRFLOW_CTX_TASK_ID=ReadData
AIRFLOW_CTX_EXECUTION_DATE=2022-12-10T00:00:00+00:00
AIRFLOW_CTX_TRY_NUMBER=3
AIRFLOW_CTX_DAG_RUN_ID=scheduled__2022-12-10T00:00:00+00:00
[2022-12-11T13:07:42.384+0000] {taskinstance.py:1772} ERROR - Task failed with exception
Traceback (most recent call last):
  File "/home/airflow/.local/lib/python3.7/site-packages/airflow/operators/python.py", line 175, in execute
    return_value = self.execute_callable()
  File "/home/airflow/.local/lib/python3.7/site-packages/airflow/operators/python.py", line 192, in execute_callable
    return self.python_callable(*self.op_args, **self.op_kwargs)
  File "/opt/airflow/dags/song.py", line 21, in ReadData
    database="postgres"
  File "/home/airflow/.local/lib/python3.7/site-packages/psycopg2/__init__.py", line 122, in connect
    conn = _connect(dsn, connection_factory=connection_factory, **kwasync)
psycopg2.OperationalError: connection to server at "103.247.196.249", port 5433 failed: Connection refused
	Is the server running on that host and accepting TCP/IP connections?

[2022-12-11T13:07:42.408+0000] {taskinstance.py:1327} INFO - Marking task as UP_FOR_RETRY. dag_id=songs, task_id=ReadData, execution_date=20221210T000000, start_date=20221211T130627, end_date=20221211T130742
[2022-12-11T13:07:42.421+0000] {standard_task_runner.py:105} ERROR - Failed to execute job 166 for task ReadData (connection to server at "103.247.196.249", port 5433 failed: Connection refused
	Is the server running on that host and accepting TCP/IP connections?
; 1272)
[2022-12-11T13:07:42.457+0000] {local_task_job.py:159} INFO - Task exited with return code 1
[2022-12-11T13:07:42.476+0000] {taskinstance.py:2582} INFO - 0 downstream tasks scheduled from follow-on schedule check
