[2022-12-13T07:12:01.793+0000] {taskinstance.py:1087} INFO - Dependencies all met for <TaskInstance: DataMart.ReadData scheduled__2022-12-11T07:00:00+00:00 [queued]>
[2022-12-13T07:12:01.800+0000] {taskinstance.py:1087} INFO - Dependencies all met for <TaskInstance: DataMart.ReadData scheduled__2022-12-11T07:00:00+00:00 [queued]>
[2022-12-13T07:12:01.800+0000] {taskinstance.py:1283} INFO - 
--------------------------------------------------------------------------------
[2022-12-13T07:12:01.801+0000] {taskinstance.py:1284} INFO - Starting attempt 4 of 6
[2022-12-13T07:12:01.801+0000] {taskinstance.py:1285} INFO - 
--------------------------------------------------------------------------------
[2022-12-13T07:12:01.809+0000] {taskinstance.py:1304} INFO - Executing <Task(PythonOperator): ReadData> on 2022-12-11 07:00:00+00:00
[2022-12-13T07:12:01.815+0000] {standard_task_runner.py:55} INFO - Started process 8097 to run task
[2022-12-13T07:12:01.819+0000] {standard_task_runner.py:82} INFO - Running: ['***', 'tasks', 'run', 'DataMart', 'ReadData', 'scheduled__2022-12-11T07:00:00+00:00', '--job-id', '336', '--raw', '--subdir', 'DAGS_FOLDER/datamart.py', '--cfg-path', '/tmp/tmpnx2fh09f']
[2022-12-13T07:12:01.821+0000] {standard_task_runner.py:83} INFO - Job 336: Subtask ReadData
[2022-12-13T07:12:01.887+0000] {task_command.py:389} INFO - Running <TaskInstance: DataMart.ReadData scheduled__2022-12-11T07:00:00+00:00 [running]> on host 83e68f36074a
[2022-12-13T07:12:01.983+0000] {taskinstance.py:1513} INFO - Exporting the following env vars:
AIRFLOW_CTX_DAG_OWNER=Gama Ariefsadya
AIRFLOW_CTX_DAG_ID=DataMart
AIRFLOW_CTX_TASK_ID=ReadData
AIRFLOW_CTX_EXECUTION_DATE=2022-12-11T07:00:00+00:00
AIRFLOW_CTX_TRY_NUMBER=4
AIRFLOW_CTX_DAG_RUN_ID=scheduled__2022-12-11T07:00:00+00:00
[2022-12-13T07:12:02.038+0000] {taskinstance.py:1772} ERROR - Task failed with exception
Traceback (most recent call last):
  File "/home/airflow/.local/lib/python3.7/site-packages/airflow/operators/python.py", line 175, in execute
    return_value = self.execute_callable()
  File "/home/airflow/.local/lib/python3.7/site-packages/airflow/operators/python.py", line 192, in execute_callable
    return self.python_callable(*self.op_args, **self.op_kwargs)
  File "/opt/airflow/dags/datamart.py", line 26, in ReadData
    cursor.execute(query)
psycopg2.errors.UndefinedTable: relation "public.artist_revenue" does not exist
LINE 1: select * from public.artist_revenue
                      ^

[2022-12-13T07:12:02.052+0000] {taskinstance.py:1327} INFO - Marking task as UP_FOR_RETRY. dag_id=DataMart, task_id=ReadData, execution_date=20221211T070000, start_date=20221213T071201, end_date=20221213T071202
[2022-12-13T07:12:02.062+0000] {standard_task_runner.py:105} ERROR - Failed to execute job 336 for task ReadData (relation "public.artist_revenue" does not exist
LINE 1: select * from public.artist_revenue
                      ^
; 8097)
[2022-12-13T07:12:02.116+0000] {local_task_job.py:159} INFO - Task exited with return code 1
[2022-12-13T07:12:02.132+0000] {taskinstance.py:2582} INFO - 0 downstream tasks scheduled from follow-on schedule check
