[2022-12-11T11:09:29.436+0000] {taskinstance.py:1087} INFO - Dependencies all met for <TaskInstance: songs_dag1.ReadData scheduled__2022-12-09T00:00:00+00:00 [queued]>
[2022-12-11T11:09:29.625+0000] {taskinstance.py:1087} INFO - Dependencies all met for <TaskInstance: songs_dag1.ReadData scheduled__2022-12-09T00:00:00+00:00 [queued]>
[2022-12-11T11:09:29.648+0000] {taskinstance.py:1283} INFO - 
--------------------------------------------------------------------------------
[2022-12-11T11:09:29.663+0000] {taskinstance.py:1284} INFO - Starting attempt 1 of 6
[2022-12-11T11:09:29.665+0000] {taskinstance.py:1285} INFO - 
--------------------------------------------------------------------------------
[2022-12-11T11:09:30.380+0000] {taskinstance.py:1304} INFO - Executing <Task(PythonOperator): ReadData> on 2022-12-09 00:00:00+00:00
[2022-12-11T11:09:30.405+0000] {standard_task_runner.py:55} INFO - Started process 1073 to run task
[2022-12-11T11:09:30.415+0000] {standard_task_runner.py:82} INFO - Running: ['***', 'tasks', 'run', 'songs_dag1', 'ReadData', 'scheduled__2022-12-09T00:00:00+00:00', '--job-id', '121', '--raw', '--subdir', 'DAGS_FOLDER/song.py', '--cfg-path', '/tmp/tmp_9gtd4km']
[2022-12-11T11:09:30.456+0000] {standard_task_runner.py:83} INFO - Job 121: Subtask ReadData
[2022-12-11T11:09:30.833+0000] {task_command.py:389} INFO - Running <TaskInstance: songs_dag1.ReadData scheduled__2022-12-09T00:00:00+00:00 [running]> on host 3211e07a3388
[2022-12-11T11:09:31.069+0000] {taskinstance.py:1513} INFO - Exporting the following env vars:
AIRFLOW_CTX_DAG_OWNER=Gama Ariefsadya
AIRFLOW_CTX_DAG_ID=songs_dag1
AIRFLOW_CTX_TASK_ID=ReadData
AIRFLOW_CTX_EXECUTION_DATE=2022-12-09T00:00:00+00:00
AIRFLOW_CTX_TRY_NUMBER=1
AIRFLOW_CTX_DAG_RUN_ID=scheduled__2022-12-09T00:00:00+00:00
[2022-12-11T11:10:46.082+0000] {taskinstance.py:1772} ERROR - Task failed with exception
Traceback (most recent call last):
  File "/home/airflow/.local/lib/python3.7/site-packages/airflow/operators/python.py", line 175, in execute
    return_value = self.execute_callable()
  File "/home/airflow/.local/lib/python3.7/site-packages/airflow/operators/python.py", line 192, in execute_callable
    return self.python_callable(*self.op_args, **self.op_kwargs)
  File "/opt/airflow/dags/song.py", line 21, in ReadData
    database="postgres"
  File "/home/airflow/.local/lib/python3.7/site-packages/psycopg2/__init__.py", line 122, in connect
    conn = _connect(dsn, connection_factory=connection_factory, **kwasync)
psycopg2.OperationalError: connection to server at "103.247.196.249", port 5433 failed: Connection refused
	Is the server running on that host and accepting TCP/IP connections?

[2022-12-11T11:10:46.164+0000] {taskinstance.py:1327} INFO - Marking task as UP_FOR_RETRY. dag_id=songs_dag1, task_id=ReadData, execution_date=20221209T000000, start_date=20221211T110929, end_date=20221211T111046
[2022-12-11T11:10:46.184+0000] {standard_task_runner.py:105} ERROR - Failed to execute job 121 for task ReadData (connection to server at "103.247.196.249", port 5433 failed: Connection refused
	Is the server running on that host and accepting TCP/IP connections?
; 1073)
[2022-12-11T11:10:46.212+0000] {local_task_job.py:159} INFO - Task exited with return code 1
[2022-12-11T11:10:46.248+0000] {taskinstance.py:2582} INFO - 0 downstream tasks scheduled from follow-on schedule check
