[2022-12-12T16:05:06.959+0000] {taskinstance.py:1087} INFO - Dependencies all met for <TaskInstance: Transaction.InsertData scheduled__2022-12-11T12:00:00+00:00 [queued]>
[2022-12-12T16:05:07.001+0000] {taskinstance.py:1087} INFO - Dependencies all met for <TaskInstance: Transaction.InsertData scheduled__2022-12-11T12:00:00+00:00 [queued]>
[2022-12-12T16:05:07.005+0000] {taskinstance.py:1283} INFO - 
--------------------------------------------------------------------------------
[2022-12-12T16:05:07.007+0000] {taskinstance.py:1284} INFO - Starting attempt 2 of 6
[2022-12-12T16:05:07.015+0000] {taskinstance.py:1285} INFO - 
--------------------------------------------------------------------------------
[2022-12-12T16:05:07.300+0000] {taskinstance.py:1304} INFO - Executing <Task(PythonOperator): InsertData> on 2022-12-11 12:00:00+00:00
[2022-12-12T16:05:07.342+0000] {standard_task_runner.py:55} INFO - Started process 72463 to run task
[2022-12-12T16:05:07.422+0000] {standard_task_runner.py:82} INFO - Running: ['***', 'tasks', 'run', 'Transaction', 'InsertData', 'scheduled__2022-12-11T12:00:00+00:00', '--job-id', '285', '--raw', '--subdir', 'DAGS_FOLDER/transaction.py', '--cfg-path', '/tmp/tmp4sllvz3i']
[2022-12-12T16:05:07.450+0000] {standard_task_runner.py:83} INFO - Job 285: Subtask InsertData
[2022-12-12T16:05:07.874+0000] {task_command.py:389} INFO - Running <TaskInstance: Transaction.InsertData scheduled__2022-12-11T12:00:00+00:00 [running]> on host 83e68f36074a
[2022-12-12T16:05:08.188+0000] {taskinstance.py:1513} INFO - Exporting the following env vars:
AIRFLOW_CTX_DAG_OWNER=Gama Ariefsadya
AIRFLOW_CTX_DAG_ID=Transaction
AIRFLOW_CTX_TASK_ID=InsertData
AIRFLOW_CTX_EXECUTION_DATE=2022-12-11T12:00:00+00:00
AIRFLOW_CTX_TRY_NUMBER=2
AIRFLOW_CTX_DAG_RUN_ID=scheduled__2022-12-11T12:00:00+00:00
[2022-12-12T16:05:08.318+0000] {taskinstance.py:1772} ERROR - Task failed with exception
Traceback (most recent call last):
  File "/home/airflow/.local/lib/python3.7/site-packages/airflow/operators/python.py", line 175, in execute
    return_value = self.execute_callable()
  File "/home/airflow/.local/lib/python3.7/site-packages/airflow/operators/python.py", line 192, in execute_callable
    return self.python_callable(*self.op_args, **self.op_kwargs)
  File "/opt/airflow/dags/transaction.py", line 63, in InsertData
    query = f"INSERT INTO public.transaction(artist_id, artist_name, album_id, album_title, track_id, track_name, invoice_line_id, invoice_id, invoice_date,billing_city) VALUES ({d['artist_id']}, '{d['artist_name']}', {d['album_id']}, '{d['album_title']}', {d['track_id']}, '{d['track_name']}', {d['invoice_line_id']}, {d['invoice_id']}, '{d['invoice_date']}','{d['billing_city']}')"
KeyError: 'billing_city'
[2022-12-12T16:05:08.384+0000] {taskinstance.py:1327} INFO - Marking task as UP_FOR_RETRY. dag_id=Transaction, task_id=InsertData, execution_date=20221211T120000, start_date=20221212T160506, end_date=20221212T160508
[2022-12-12T16:05:08.435+0000] {standard_task_runner.py:105} ERROR - Failed to execute job 285 for task InsertData ('billing_city'; 72463)
[2022-12-12T16:05:08.532+0000] {local_task_job.py:159} INFO - Task exited with return code 1
[2022-12-12T16:05:08.591+0000] {taskinstance.py:2582} INFO - 0 downstream tasks scheduled from follow-on schedule check
