[2022-12-11T11:03:53.726+0000] {taskinstance.py:1087} INFO - Dependencies all met for <TaskInstance: songs_dag.ReadData scheduled__2022-12-10T00:00:00+00:00 [queued]>
[2022-12-11T11:03:53.734+0000] {taskinstance.py:1087} INFO - Dependencies all met for <TaskInstance: songs_dag.ReadData scheduled__2022-12-10T00:00:00+00:00 [queued]>
[2022-12-11T11:03:53.734+0000] {taskinstance.py:1283} INFO - 
--------------------------------------------------------------------------------
[2022-12-11T11:03:53.735+0000] {taskinstance.py:1284} INFO - Starting attempt 2 of 7
[2022-12-11T11:03:53.735+0000] {taskinstance.py:1285} INFO - 
--------------------------------------------------------------------------------
[2022-12-11T11:03:53.743+0000] {taskinstance.py:1304} INFO - Executing <Task(PythonOperator): ReadData> on 2022-12-10 00:00:00+00:00
[2022-12-11T11:03:53.749+0000] {standard_task_runner.py:55} INFO - Started process 622 to run task
[2022-12-11T11:03:53.753+0000] {standard_task_runner.py:82} INFO - Running: ['***', 'tasks', 'run', 'songs_dag', 'ReadData', 'scheduled__2022-12-10T00:00:00+00:00', '--job-id', '111', '--raw', '--subdir', 'DAGS_FOLDER/song.py', '--cfg-path', '/tmp/tmpm_q4ckgc']
[2022-12-11T11:03:53.757+0000] {standard_task_runner.py:83} INFO - Job 111: Subtask ReadData
[2022-12-11T11:03:53.843+0000] {task_command.py:389} INFO - Running <TaskInstance: songs_dag.ReadData scheduled__2022-12-10T00:00:00+00:00 [running]> on host 3211e07a3388
[2022-12-11T11:03:53.896+0000] {taskinstance.py:1513} INFO - Exporting the following env vars:
AIRFLOW_CTX_DAG_OWNER=Gama Ariefsadya
AIRFLOW_CTX_DAG_ID=songs_dag
AIRFLOW_CTX_TASK_ID=ReadData
AIRFLOW_CTX_EXECUTION_DATE=2022-12-10T00:00:00+00:00
AIRFLOW_CTX_TRY_NUMBER=2
AIRFLOW_CTX_DAG_RUN_ID=scheduled__2022-12-10T00:00:00+00:00
[2022-12-11T11:04:08.951+0000] {local_task_job.py:224} WARNING - State of this instance has been externally set to up_for_retry. Terminating instance.
[2022-12-11T11:04:08.966+0000] {process_utils.py:133} INFO - Sending Signals.SIGTERM to group 622. PIDs of all processes in the group: [622]
[2022-12-11T11:04:08.968+0000] {process_utils.py:84} INFO - Sending the signal Signals.SIGTERM to group 622
[2022-12-11T11:05:08.902+0000] {taskinstance.py:1483} ERROR - Received SIGTERM. Terminating subprocesses.
[2022-12-11T11:05:08.956+0000] {taskinstance.py:1772} ERROR - Task failed with exception
Traceback (most recent call last):
  File "/home/airflow/.local/lib/python3.7/site-packages/airflow/models/taskinstance.py", line 1524, in _execute_task_with_callbacks
    result = self._execute_task(context, task_orig)
  File "/home/airflow/.local/lib/python3.7/site-packages/airflow/models/taskinstance.py", line 1585, in _execute_task
    result = execute_callable(context=context)
  File "/home/airflow/.local/lib/python3.7/site-packages/airflow/operators/python.py", line 175, in execute
    return_value = self.execute_callable()
  File "/home/airflow/.local/lib/python3.7/site-packages/airflow/operators/python.py", line 192, in execute_callable
    return self.python_callable(*self.op_args, **self.op_kwargs)
  File "/opt/airflow/dags/song.py", line 21, in ReadData
    database="postgres"
  File "/home/airflow/.local/lib/python3.7/site-packages/psycopg2/__init__.py", line 122, in connect
    conn = _connect(dsn, connection_factory=connection_factory, **kwasync)
psycopg2.OperationalError: connection to server at "103.247.196.249", port 5433 failed: Connection refused
	Is the server running on that host and accepting TCP/IP connections?


During handling of the above exception, another exception occurred:

Traceback (most recent call last):
  File "/home/airflow/.local/lib/python3.7/site-packages/airflow/models/taskinstance.py", line 1378, in _run_raw_task
    self._execute_task_with_callbacks(context, test_mode)
  File "/home/airflow/.local/lib/python3.7/site-packages/airflow/models/taskinstance.py", line 1524, in _execute_task_with_callbacks
    result = self._execute_task(context, task_orig)
  File "/home/airflow/.local/lib/python3.7/site-packages/airflow/models/taskinstance.py", line 1485, in signal_handler
    raise AirflowException("Task received SIGTERM signal")
airflow.exceptions.AirflowException: Task received SIGTERM signal
[2022-12-11T11:05:08.967+0000] {taskinstance.py:1327} INFO - Marking task as UP_FOR_RETRY. dag_id=songs_dag, task_id=ReadData, execution_date=20221210T000000, start_date=20221211T110353, end_date=20221211T110508
[2022-12-11T11:05:08.985+0000] {standard_task_runner.py:105} ERROR - Failed to execute job 111 for task ReadData (Task received SIGTERM signal; 622)
[2022-12-11T11:05:08.989+0000] {process_utils.py:147} WARNING - process psutil.Process(pid=622, name='airflow task ru', status='running', started='11:03:52') did not respond to SIGTERM. Trying SIGKILL
[2022-12-11T11:05:09.006+0000] {process_utils.py:84} INFO - Sending the signal Signals.SIGKILL to group 622
[2022-12-11T11:05:09.021+0000] {process_utils.py:79} INFO - Process psutil.Process(pid=622, name='airflow task ru', status='terminated', exitcode=1, started='11:03:52') (622) terminated with exit code 1
