[2022-12-11T11:09:02.278+0000] {taskinstance.py:1087} INFO - Dependencies all met for <TaskInstance: songs_dag.ReadData scheduled__2022-12-10T00:00:00+00:00 [queued]>
[2022-12-11T11:09:02.287+0000] {taskinstance.py:1087} INFO - Dependencies all met for <TaskInstance: songs_dag.ReadData scheduled__2022-12-10T00:00:00+00:00 [queued]>
[2022-12-11T11:09:02.288+0000] {taskinstance.py:1283} INFO - 
--------------------------------------------------------------------------------
[2022-12-11T11:09:02.288+0000] {taskinstance.py:1284} INFO - Starting attempt 4 of 8
[2022-12-11T11:09:02.289+0000] {taskinstance.py:1285} INFO - 
--------------------------------------------------------------------------------
[2022-12-11T11:09:02.309+0000] {taskinstance.py:1304} INFO - Executing <Task(PythonOperator): ReadData> on 2022-12-10 00:00:00+00:00
[2022-12-11T11:09:02.316+0000] {standard_task_runner.py:55} INFO - Started process 1027 to run task
[2022-12-11T11:09:02.322+0000] {standard_task_runner.py:82} INFO - Running: ['***', 'tasks', 'run', 'songs_dag', 'ReadData', 'scheduled__2022-12-10T00:00:00+00:00', '--job-id', '114', '--raw', '--subdir', 'DAGS_FOLDER/song.py', '--cfg-path', '/tmp/tmp0lu5aa_o']
[2022-12-11T11:09:02.329+0000] {standard_task_runner.py:83} INFO - Job 114: Subtask ReadData
[2022-12-11T11:09:02.537+0000] {task_command.py:389} INFO - Running <TaskInstance: songs_dag.ReadData scheduled__2022-12-10T00:00:00+00:00 [running]> on host 3211e07a3388
[2022-12-11T11:09:02.687+0000] {taskinstance.py:1513} INFO - Exporting the following env vars:
AIRFLOW_CTX_DAG_OWNER=Gama Ariefsadya
AIRFLOW_CTX_DAG_ID=songs_dag
AIRFLOW_CTX_TASK_ID=ReadData
AIRFLOW_CTX_EXECUTION_DATE=2022-12-10T00:00:00+00:00
AIRFLOW_CTX_TRY_NUMBER=4
AIRFLOW_CTX_DAG_RUN_ID=scheduled__2022-12-10T00:00:00+00:00
[2022-12-11T11:10:17.705+0000] {taskinstance.py:1772} ERROR - Task failed with exception
Traceback (most recent call last):
  File "/home/airflow/.local/lib/python3.7/site-packages/airflow/operators/python.py", line 175, in execute
    return_value = self.execute_callable()
  File "/home/airflow/.local/lib/python3.7/site-packages/airflow/operators/python.py", line 192, in execute_callable
    return self.python_callable(*self.op_args, **self.op_kwargs)
  File "/opt/airflow/dags/song.py", line 21, in ReadData
    database="postgres"
  File "/home/airflow/.local/lib/python3.7/site-packages/psycopg2/__init__.py", line 122, in connect
    conn = _connect(dsn, connection_factory=connection_factory, **kwasync)
psycopg2.OperationalError: connection to server at "103.247.196.249", port 5433 failed: Connection refused
	Is the server running on that host and accepting TCP/IP connections?

[2022-12-11T11:10:17.739+0000] {taskinstance.py:1327} INFO - Marking task as UP_FOR_RETRY. dag_id=songs_dag, task_id=ReadData, execution_date=20221210T000000, start_date=20221211T110902, end_date=20221211T111017
[2022-12-11T11:10:17.758+0000] {standard_task_runner.py:105} ERROR - Failed to execute job 114 for task ReadData (connection to server at "103.247.196.249", port 5433 failed: Connection refused
	Is the server running on that host and accepting TCP/IP connections?
; 1027)
[2022-12-11T11:10:17.815+0000] {local_task_job.py:159} INFO - Task exited with return code 1
[2022-12-11T11:10:17.840+0000] {taskinstance.py:2582} INFO - 0 downstream tasks scheduled from follow-on schedule check
