[2022-12-11T11:02:45.353+0000] {taskinstance.py:1087} INFO - Dependencies all met for <TaskInstance: songs_dag.ReadData scheduled__2022-12-10T00:00:00+00:00 [queued]>
[2022-12-11T11:02:45.360+0000] {taskinstance.py:1087} INFO - Dependencies all met for <TaskInstance: songs_dag.ReadData scheduled__2022-12-10T00:00:00+00:00 [queued]>
[2022-12-11T11:02:45.361+0000] {taskinstance.py:1283} INFO - 
--------------------------------------------------------------------------------
[2022-12-11T11:02:45.362+0000] {taskinstance.py:1284} INFO - Starting attempt 1 of 6
[2022-12-11T11:02:45.362+0000] {taskinstance.py:1285} INFO - 
--------------------------------------------------------------------------------
[2022-12-11T11:02:45.372+0000] {taskinstance.py:1304} INFO - Executing <Task(PythonOperator): ReadData> on 2022-12-10 00:00:00+00:00
[2022-12-11T11:02:45.377+0000] {standard_task_runner.py:55} INFO - Started process 537 to run task
[2022-12-11T11:02:45.381+0000] {standard_task_runner.py:82} INFO - Running: ['***', 'tasks', 'run', 'songs_dag', 'ReadData', 'scheduled__2022-12-10T00:00:00+00:00', '--job-id', '110', '--raw', '--subdir', 'DAGS_FOLDER/song.py', '--cfg-path', '/tmp/tmp9t763qu8']
[2022-12-11T11:02:45.383+0000] {standard_task_runner.py:83} INFO - Job 110: Subtask ReadData
[2022-12-11T11:02:45.452+0000] {task_command.py:389} INFO - Running <TaskInstance: songs_dag.ReadData scheduled__2022-12-10T00:00:00+00:00 [running]> on host 3211e07a3388
[2022-12-11T11:02:45.522+0000] {taskinstance.py:1513} INFO - Exporting the following env vars:
AIRFLOW_CTX_DAG_OWNER=Gama Ariefsadya
AIRFLOW_CTX_DAG_ID=songs_dag
AIRFLOW_CTX_TASK_ID=ReadData
AIRFLOW_CTX_EXECUTION_DATE=2022-12-10T00:00:00+00:00
AIRFLOW_CTX_TRY_NUMBER=1
AIRFLOW_CTX_DAG_RUN_ID=scheduled__2022-12-10T00:00:00+00:00
[2022-12-11T11:03:51.453+0000] {local_task_job.py:224} WARNING - State of this instance has been externally set to restarting. Terminating instance.
[2022-12-11T11:03:51.465+0000] {process_utils.py:133} INFO - Sending Signals.SIGTERM to group 537. PIDs of all processes in the group: [537]
[2022-12-11T11:03:51.466+0000] {process_utils.py:84} INFO - Sending the signal Signals.SIGTERM to group 537
[2022-12-11T11:04:00.542+0000] {taskinstance.py:1483} ERROR - Received SIGTERM. Terminating subprocesses.
[2022-12-11T11:04:00.594+0000] {taskinstance.py:1772} ERROR - Task failed with exception
Traceback (most recent call last):
  File "/home/airflow/.local/lib/python3.7/site-packages/airflow/models/taskinstance.py", line 1524, in _execute_task_with_callbacks
    result = self._execute_task(context, task_orig)
  File "/home/airflow/.local/lib/python3.7/site-packages/airflow/models/taskinstance.py", line 1585, in _execute_task
    result = execute_callable(context=context)
  File "/home/airflow/.local/lib/python3.7/site-packages/airflow/operators/python.py", line 175, in execute
    return_value = self.execute_callable()
  File "/home/airflow/.local/lib/python3.7/site-packages/airflow/operators/python.py", line 192, in execute_callable
    return self.python_callable(*self.op_args, **self.op_kwargs)
  File "/opt/airflow/dags/song.py", line 21, in ReadData
    database="postgres"
  File "/home/airflow/.local/lib/python3.7/site-packages/psycopg2/__init__.py", line 122, in connect
    conn = _connect(dsn, connection_factory=connection_factory, **kwasync)
psycopg2.OperationalError: connection to server at "103.247.196.249", port 5433 failed: Connection refused
	Is the server running on that host and accepting TCP/IP connections?


During handling of the above exception, another exception occurred:

Traceback (most recent call last):
  File "/home/airflow/.local/lib/python3.7/site-packages/airflow/models/taskinstance.py", line 1378, in _run_raw_task
    self._execute_task_with_callbacks(context, test_mode)
  File "/home/airflow/.local/lib/python3.7/site-packages/airflow/models/taskinstance.py", line 1524, in _execute_task_with_callbacks
    result = self._execute_task(context, task_orig)
  File "/home/airflow/.local/lib/python3.7/site-packages/airflow/models/taskinstance.py", line 1485, in signal_handler
    raise AirflowException("Task received SIGTERM signal")
airflow.exceptions.AirflowException: Task received SIGTERM signal
[2022-12-11T11:04:00.604+0000] {taskinstance.py:1327} INFO - Marking task as UP_FOR_RETRY. dag_id=songs_dag, task_id=ReadData, execution_date=20221210T000000, start_date=20221211T110353, end_date=20221211T110400
[2022-12-11T11:04:00.621+0000] {standard_task_runner.py:105} ERROR - Failed to execute job 110 for task ReadData (Task received SIGTERM signal; 537)
[2022-12-11T11:04:00.654+0000] {process_utils.py:79} INFO - Process psutil.Process(pid=537, status='terminated', exitcode=1, started='11:02:44') (537) terminated with exit code 1
