[2022-12-13T07:10:02.969+0000] {taskinstance.py:1087} INFO - Dependencies all met for <TaskInstance: DataMart.ReadData scheduled__2022-12-12T07:00:00+00:00 [queued]>
[2022-12-13T07:10:02.978+0000] {taskinstance.py:1087} INFO - Dependencies all met for <TaskInstance: DataMart.ReadData scheduled__2022-12-12T07:00:00+00:00 [queued]>
[2022-12-13T07:10:02.979+0000] {taskinstance.py:1283} INFO - 
--------------------------------------------------------------------------------
[2022-12-13T07:10:02.979+0000] {taskinstance.py:1284} INFO - Starting attempt 6 of 11
[2022-12-13T07:10:02.980+0000] {taskinstance.py:1285} INFO - 
--------------------------------------------------------------------------------
[2022-12-13T07:10:03.001+0000] {taskinstance.py:1304} INFO - Executing <Task(PythonOperator): ReadData> on 2022-12-12 07:00:00+00:00
[2022-12-13T07:10:03.013+0000] {standard_task_runner.py:55} INFO - Started process 7891 to run task
[2022-12-13T07:10:03.017+0000] {standard_task_runner.py:82} INFO - Running: ['***', 'tasks', 'run', 'DataMart', 'ReadData', 'scheduled__2022-12-12T07:00:00+00:00', '--job-id', '334', '--raw', '--subdir', 'DAGS_FOLDER/datamart.py', '--cfg-path', '/tmp/tmp_4u9z1xg']
[2022-12-13T07:10:03.019+0000] {standard_task_runner.py:83} INFO - Job 334: Subtask ReadData
[2022-12-13T07:10:03.085+0000] {task_command.py:389} INFO - Running <TaskInstance: DataMart.ReadData scheduled__2022-12-12T07:00:00+00:00 [running]> on host 83e68f36074a
[2022-12-13T07:10:03.147+0000] {taskinstance.py:1513} INFO - Exporting the following env vars:
AIRFLOW_CTX_DAG_OWNER=Gama Ariefsadya
AIRFLOW_CTX_DAG_ID=DataMart
AIRFLOW_CTX_TASK_ID=ReadData
AIRFLOW_CTX_EXECUTION_DATE=2022-12-12T07:00:00+00:00
AIRFLOW_CTX_TRY_NUMBER=6
AIRFLOW_CTX_DAG_RUN_ID=scheduled__2022-12-12T07:00:00+00:00
[2022-12-13T07:10:03.161+0000] {taskinstance.py:1772} ERROR - Task failed with exception
Traceback (most recent call last):
  File "/home/airflow/.local/lib/python3.7/site-packages/airflow/operators/python.py", line 175, in execute
    return_value = self.execute_callable()
  File "/home/airflow/.local/lib/python3.7/site-packages/airflow/operators/python.py", line 192, in execute_callable
    return self.python_callable(*self.op_args, **self.op_kwargs)
  File "/opt/airflow/dags/datamart.py", line 26, in ReadData
    cursor.execute(query)
psycopg2.errors.UndefinedTable: relation "public.artist_revenue" does not exist
LINE 1: select * from "public.artist_revenue"
                      ^

[2022-12-13T07:10:03.171+0000] {taskinstance.py:1327} INFO - Marking task as UP_FOR_RETRY. dag_id=DataMart, task_id=ReadData, execution_date=20221212T070000, start_date=20221213T071002, end_date=20221213T071003
[2022-12-13T07:10:03.178+0000] {standard_task_runner.py:105} ERROR - Failed to execute job 334 for task ReadData (relation "public.artist_revenue" does not exist
LINE 1: select * from "public.artist_revenue"
                      ^
; 7891)
[2022-12-13T07:10:03.188+0000] {local_task_job.py:159} INFO - Task exited with return code 1
[2022-12-13T07:10:03.204+0000] {taskinstance.py:2582} INFO - 0 downstream tasks scheduled from follow-on schedule check
